"""
リカバリー機能のテスト

このテストはRed Phase用で、すべて失敗することを確認する
"""

import unittest
import sys
from pathlib import Path
from unittest.mock import Mock, patch
import time

# パス設定
sys.path.append(str(Path(__file__).parent.parent.parent.parent / "src"))

from attendance_tool.errors.recovery import RecoveryManager


class TestRecoveryManager(unittest.TestCase):
    """リカバリー機能テストクラス"""

    def setUp(self):
        """テスト前準備"""
        # RecoveryManagerは未実装なので、インスタンス化で失敗するはず
        self.recovery_manager = RecoveryManager()

    def test_io_error_retry(self):
        """I/Oエラーリトライ機能テスト (TC-401-010)"""
        # モックファイル読み込み関数（最初の2回は失敗、3回目で成功）
        mock_file_read = Mock(
            side_effect=[
                IOError("Network issue"),
                IOError("Temporary failure"),
                "Success",
            ]
        )

        # retry_operationメソッドは未実装なので失敗するはず
        result = self.recovery_manager.retry_operation(
            operation=mock_file_read, max_retries=3, delay=0.1
        )

        # 期待結果
        self.assertEqual(result, "Success")
        self.assertEqual(mock_file_read.call_count, 3)

    def test_memory_error_recovery(self):
        """メモリ不足時の自動回復テスト (TC-401-011)"""

        # メモリエラーのシミュレーション
        def memory_intensive_operation():
            raise MemoryError("Out of memory")

        # handle_memory_errorメソッドは未実装なので失敗するはず
        recovery_result = self.recovery_manager.handle_memory_error(
            operation=memory_intensive_operation
        )

        # 期待結果
        self.assertTrue(recovery_result.gc_executed)
        self.assertTrue(recovery_result.memory_freed > 0)
        self.assertIsNotNone(recovery_result.recovery_success)

    def test_partial_data_error_continuation(self):
        """部分的データエラーでの継続処理テスト (TC-401-012)"""
        # テストデータ（一部にエラーを含む）
        test_data = [
            {"employee_id": "001", "date": "2024-01-01", "valid": True},
            {"employee_id": "002", "date": "invalid-date", "valid": False},  # エラー
            {"employee_id": "003", "date": "2024-01-01", "valid": True},
        ]

        def process_record(record):
            if not record["valid"]:
                raise ValueError("Invalid data")
            return f"Processed {record['employee_id']}"

        # process_with_error_continuationメソッドは未実装なので失敗するはず
        result = self.recovery_manager.process_with_error_continuation(
            data=test_data, processor=process_record
        )

        # 期待結果
        self.assertEqual(len(result.successful_results), 2)
        self.assertEqual(len(result.error_records), 1)
        self.assertIn("002", result.error_records[0].record_id)


if __name__ == "__main__":
    unittest.main()
