"""
エラー分類・重要度判定のテスト

このテストはRed Phase用で、すべて失敗することを確認する
"""

import sys
import unittest
from pathlib import Path

# パス設定
sys.path.append(str(Path(__file__).parent.parent.parent.parent / "src"))

from attendance_tool.errors.exceptions import (
    AttendanceToolError,
    BusinessError,
    DataError,
    SystemError,
    UserError,
)
from attendance_tool.errors.handler import ErrorHandler


class TestErrorClassification(unittest.TestCase):
    """エラー分類テストクラス"""

    def setUp(self):
        """テスト前準備"""
        # ErrorHandlerは未実装なので、インスタンス化で失敗するはず
        self.error_handler = ErrorHandler()

    def test_system_error_classification(self):
        """システムエラーの分類テスト (TC-401-001)"""
        test_cases = [
            {
                "exception": FileNotFoundError("/path/to/missing.csv"),
                "expected_category": "SYSTEM",
                "expected_code": "SYS-001",
                "expected_severity": "ERROR",
            },
            {
                "exception": PermissionError("Access denied"),
                "expected_category": "SYSTEM",
                "expected_code": "SYS-004",
                "expected_severity": "CRITICAL",
            },
            {
                "exception": MemoryError("Out of memory"),
                "expected_category": "SYSTEM",
                "expected_code": "SYS-003",
                "expected_severity": "CRITICAL",
            },
        ]

        for case in test_cases:
            with self.subTest(case=case):
                # classify_errorメソッドは未実装なので失敗するはず
                result = self.error_handler.classify_error(case["exception"])

                self.assertEqual(result.category, case["expected_category"])
                self.assertEqual(result.code, case["expected_code"])
                self.assertEqual(result.severity, case["expected_severity"])

    def test_data_error_classification(self):
        """データエラーの分類テスト (TC-401-002)"""
        from attendance_tool.validation.models import TimeLogicError, ValidationError

        test_cases = [
            {
                "exception": ValidationError("Invalid date format", field="date"),
                "expected_category": "DATA",
                "expected_code": "DATA-001",
                "expected_severity": "WARNING",
            },
            {
                "exception": TimeLogicError("Start time > End time"),
                "expected_category": "DATA",
                "expected_code": "DATA-201",
                "expected_severity": "ERROR",
            },
        ]

        for case in test_cases:
            with self.subTest(case=case):
                # 未実装なので失敗するはず
                result = self.error_handler.classify_error(case["exception"])

                self.assertEqual(result.category, case["expected_category"])
                self.assertEqual(result.code, case["expected_code"])
                self.assertEqual(result.severity, case["expected_severity"])

    def test_business_error_classification(self):
        """ビジネスロジックエラーの分類テスト (TC-401-003)"""
        from attendance_tool.validation.models import WorkHoursError

        test_cases = [
            {
                "exception": WorkHoursError("Work hours exceed 24h"),
                "expected_category": "BUSINESS",
                "expected_code": "BIZ-104",
                "expected_severity": "WARNING",
            }
        ]

        for case in test_cases:
            with self.subTest(case=case):
                # 未実装なので失敗するはず
                result = self.error_handler.classify_error(case["exception"])

                self.assertEqual(result.category, case["expected_category"])
                self.assertEqual(result.code, case["expected_code"])
                self.assertEqual(result.severity, case["expected_severity"])


if __name__ == "__main__":
    unittest.main()
